/usr/lib/python3.7/unittest/case.py:624: ResourceWarning: unclosed <ssl.SSLSocket fd=5, family=AddressFamily.AF_INET, type=SocketKind.SOCK_STREAM, proto=6, laddr=('10.0.0.71', 47098), raddr=('52.218.234.9', 443)>
  self.setUp()
ResourceWarning: Enable tracemalloc to get the object allocation traceback
F/usr/lib/python3.7/unittest/case.py:624: ResourceWarning: unclosed <ssl.SSLSocket fd=5, family=AddressFamily.AF_INET, type=SocketKind.SOCK_STREAM, proto=6, laddr=('10.0.0.71', 47100), raddr=('52.218.234.9', 443)>
  self.setUp()
ResourceWarning: Enable tracemalloc to get the object allocation traceback
.
======================================================================
FAIL: test_for_closed_date_greater_than_created_date (unit_test.test_cleaned.DateTestCase)
----------------------------------------------------------------------
marbles.core.marbles.ContextualAssertionError: Se detectaron 3831 casos en los que la closed_date sucede antes que la created_date.

Source (/home/jp/data-product-architecture-final-project/scripts/luigi/unit_test/test_cleaned.py):
     52 _valid = self.df['closed_date'] >= self.df['created_date']
 >   53 self.assertTrue(all(_valid), msg=msg, note=note)
     54 
Note:
	Es imposible que un issue se cierre antes de ser abierto, actualmente
	existen casos en los que esta sucediendo esto.


----------------------------------------------------------------------
Ran 2 tests in 0.348s

FAILED (failures=1)
